[2024-06-18T18:01:00.374+0545] {local_task_job_runner.py:120} INFO - ::group::Pre task execution logs
[2024-06-18T18:01:00.403+0545] {taskinstance.py:2076} INFO - Dependencies all met for dep_context=non-requeueable deps ti=<TaskInstance: Backup_Database.backup_task manual__2024-06-18T12:14:02.125451+00:00 [queued]>
[2024-06-18T18:01:00.410+0545] {taskinstance.py:2076} INFO - Dependencies all met for dep_context=requeueable deps ti=<TaskInstance: Backup_Database.backup_task manual__2024-06-18T12:14:02.125451+00:00 [queued]>
[2024-06-18T18:01:00.411+0545] {taskinstance.py:2306} INFO - Starting attempt 2 of 2
[2024-06-18T18:01:00.483+0545] {taskinstance.py:2330} INFO - Executing <Task(BashOperator): backup_task> on 2024-06-18 12:14:02.125451+00:00
[2024-06-18T18:01:00.491+0545] {standard_task_runner.py:63} INFO - Started process 28363 to run task
[2024-06-18T18:01:00.499+0545] {standard_task_runner.py:90} INFO - Running: ['airflow', 'tasks', 'run', 'Backup_Database', 'backup_task', 'manual__2024-06-18T12:14:02.125451+00:00', '--job-id', '148', '--raw', '--subdir', 'DAGS_FOLDER/basic_dag.py', '--cfg-path', '/tmp/tmpsbbaso2x']
[2024-06-18T18:01:00.504+0545] {standard_task_runner.py:91} INFO - Job 148: Subtask backup_task
[2024-06-18T18:01:00.652+0545] {task_command.py:426} INFO - Running <TaskInstance: Backup_Database.backup_task manual__2024-06-18T12:14:02.125451+00:00 [running]> on host manisha-Inspiron-3580
[2024-06-18T18:01:00.930+0545] {taskinstance.py:2648} INFO - Exporting env vars: AIRFLOW_CTX_DAG_OWNER='manisha' AIRFLOW_CTX_DAG_ID='Backup_Database' AIRFLOW_CTX_TASK_ID='backup_task' AIRFLOW_CTX_EXECUTION_DATE='2024-06-18T12:14:02.125451+00:00' AIRFLOW_CTX_TRY_NUMBER='2' AIRFLOW_CTX_DAG_RUN_ID='manual__2024-06-18T12:14:02.125451+00:00'
[2024-06-18T18:01:00.931+0545] {taskinstance.py:430} INFO - ::endgroup::
[2024-06-18T18:01:00.943+0545] {subprocess.py:63} INFO - Tmp dir root location: /tmp
[2024-06-18T18:01:00.944+0545] {subprocess.py:75} INFO - Running command: ['/usr/bin/bash', '-c', '/home/manisha/airflow/bashScripts/backup.sh ']
[2024-06-18T18:01:00.949+0545] {subprocess.py:86} INFO - Output:
[2024-06-18T18:01:22.732+0545] {subprocess.py:93} INFO - Enter password: ERROR 1045 (28000): Access denied for user 'manisha'@'localhost' (using password: NO)
[2024-06-18T18:01:22.736+0545] {subprocess.py:93} INFO - (standard_in) 1: syntax error
[2024-06-18T18:01:23.014+0545] {subprocess.py:93} INFO - /home/manisha/airflow/bashScripts/backup.sh: line 36: /airflow_db_2024-06-1818:01:23.sql: Permission denied
[2024-06-18T18:01:23.036+0545] {subprocess.py:93} INFO - Backup completed in 0 seconds
[2024-06-18T18:01:23.038+0545] {subprocess.py:93} INFO - Backup Success in location: /home/manisha/airflow/backup|Required Space: GB, Available Space: 428.25GB
[2024-06-18T18:01:23.041+0545] {subprocess.py:93} INFO - /home/manisha/airflow/bashScripts/backup.sh: line 69: /airflow_db2024-06-1818:01:23.sql: Permission denied
[2024-06-18T18:01:23.043+0545] {subprocess.py:97} INFO - Command exited with return code 1
[2024-06-18T18:01:23.133+0545] {taskinstance.py:441} INFO - ::group::Post task execution logs
[2024-06-18T18:01:23.178+0545] {taskinstance.py:2905} ERROR - Task failed with exception
Traceback (most recent call last):
  File "/home/manisha/airflow_env/lib/python3.10/site-packages/airflow/models/taskinstance.py", line 465, in _execute_task
    result = _execute_callable(context=context, **execute_callable_kwargs)
  File "/home/manisha/airflow_env/lib/python3.10/site-packages/airflow/models/taskinstance.py", line 432, in _execute_callable
    return execute_callable(context=context, **execute_callable_kwargs)
  File "/home/manisha/airflow_env/lib/python3.10/site-packages/airflow/models/baseoperator.py", line 401, in wrapper
    return func(self, *args, **kwargs)
  File "/home/manisha/airflow_env/lib/python3.10/site-packages/airflow/operators/bash.py", line 243, in execute
    raise AirflowException(
airflow.exceptions.AirflowException: Bash command failed. The command returned a non-zero exit code 1.
[2024-06-18T18:01:23.185+0545] {taskinstance.py:1206} INFO - Marking task as FAILED. dag_id=Backup_Database, task_id=backup_task, run_id=manual__2024-06-18T12:14:02.125451+00:00, execution_date=20240618T121402, start_date=20240618T121600, end_date=20240618T121623
[2024-06-18T18:01:25.196+0545] {standard_task_runner.py:110} ERROR - Failed to execute job 148 for task backup_task ((MySQLdb.OperationalError) (2013, 'Lost connection to MySQL server during query')
(Background on this error at: https://sqlalche.me/e/14/e3q8); 28363)
