[2024-06-18T13:58:50.726+0545] {local_task_job_runner.py:120} INFO - ::group::Pre task execution logs
[2024-06-18T13:58:50.753+0545] {taskinstance.py:2076} INFO - Dependencies all met for dep_context=non-requeueable deps ti=<TaskInstance: Backup_Database.backup_task manual__2024-06-18T08:12:47.942072+00:00 [queued]>
[2024-06-18T13:58:50.760+0545] {taskinstance.py:2076} INFO - Dependencies all met for dep_context=requeueable deps ti=<TaskInstance: Backup_Database.backup_task manual__2024-06-18T08:12:47.942072+00:00 [queued]>
[2024-06-18T13:58:50.760+0545] {taskinstance.py:2306} INFO - Starting attempt 2 of 2
[2024-06-18T13:58:50.854+0545] {taskinstance.py:2330} INFO - Executing <Task(BashOperator): backup_task> on 2024-06-18 08:12:47.942072+00:00
[2024-06-18T13:58:50.861+0545] {standard_task_runner.py:63} INFO - Started process 16397 to run task
[2024-06-18T13:58:50.869+0545] {standard_task_runner.py:90} INFO - Running: ['airflow', 'tasks', 'run', 'Backup_Database', 'backup_task', 'manual__2024-06-18T08:12:47.942072+00:00', '--job-id', '34', '--raw', '--subdir', 'DAGS_FOLDER/basic_dag.py', '--cfg-path', '/tmp/tmpoz4fbbma']
[2024-06-18T13:58:50.872+0545] {standard_task_runner.py:91} INFO - Job 34: Subtask backup_task
[2024-06-18T13:58:51.045+0545] {task_command.py:426} INFO - Running <TaskInstance: Backup_Database.backup_task manual__2024-06-18T08:12:47.942072+00:00 [running]> on host manisha-Inspiron-3580
[2024-06-18T13:58:51.192+0545] {taskinstance.py:2648} INFO - Exporting env vars: AIRFLOW_CTX_DAG_OWNER='manisha' AIRFLOW_CTX_DAG_ID='Backup_Database' AIRFLOW_CTX_TASK_ID='backup_task' AIRFLOW_CTX_EXECUTION_DATE='2024-06-18T08:12:47.942072+00:00' AIRFLOW_CTX_TRY_NUMBER='2' AIRFLOW_CTX_DAG_RUN_ID='manual__2024-06-18T08:12:47.942072+00:00'
[2024-06-18T13:58:51.193+0545] {taskinstance.py:430} INFO - ::endgroup::
[2024-06-18T13:58:51.203+0545] {subprocess.py:63} INFO - Tmp dir root location: /tmp
[2024-06-18T13:58:51.204+0545] {subprocess.py:75} INFO - Running command: ['/usr/bin/bash', '-c', '/root/backup.sh ']
[2024-06-18T13:58:51.209+0545] {subprocess.py:86} INFO - Output:
[2024-06-18T13:58:51.209+0545] {subprocess.py:93} INFO - /usr/bin/bash: line 1: /root/backup.sh: Permission denied
[2024-06-18T13:58:51.210+0545] {subprocess.py:97} INFO - Command exited with return code 126
[2024-06-18T13:58:51.210+0545] {taskinstance.py:441} INFO - ::group::Post task execution logs
[2024-06-18T13:58:51.221+0545] {taskinstance.py:2905} ERROR - Task failed with exception
Traceback (most recent call last):
  File "/home/manisha/airflow_env/lib/python3.10/site-packages/airflow/models/taskinstance.py", line 465, in _execute_task
    result = _execute_callable(context=context, **execute_callable_kwargs)
  File "/home/manisha/airflow_env/lib/python3.10/site-packages/airflow/models/taskinstance.py", line 432, in _execute_callable
    return execute_callable(context=context, **execute_callable_kwargs)
  File "/home/manisha/airflow_env/lib/python3.10/site-packages/airflow/models/baseoperator.py", line 401, in wrapper
    return func(self, *args, **kwargs)
  File "/home/manisha/airflow_env/lib/python3.10/site-packages/airflow/operators/bash.py", line 243, in execute
    raise AirflowException(
airflow.exceptions.AirflowException: Bash command failed. The command returned a non-zero exit code 126.
[2024-06-18T13:58:51.223+0545] {taskinstance.py:1206} INFO - Marking task as FAILED. dag_id=Backup_Database, task_id=backup_task, run_id=manual__2024-06-18T08:12:47.942072+00:00, execution_date=20240618T081247, start_date=20240618T081350, end_date=20240618T081351
[2024-06-18T13:58:51.294+0545] {standard_task_runner.py:110} ERROR - Failed to execute job 34 for task backup_task (Bash command failed. The command returned a non-zero exit code 126.; 16397)
[2024-06-18T13:58:51.322+0545] {local_task_job_runner.py:240} INFO - Task exited with return code 1
[2024-06-18T13:58:51.398+0545] {taskinstance.py:3503} INFO - 0 downstream tasks scheduled from follow-on schedule check
[2024-06-18T13:58:51.449+0545] {local_task_job_runner.py:222} INFO - ::endgroup::
