[2024-06-18T14:17:10.791+0545] {local_task_job_runner.py:120} INFO - ::group::Pre task execution logs
[2024-06-18T14:17:10.815+0545] {taskinstance.py:2076} INFO - Dependencies all met for dep_context=non-requeueable deps ti=<TaskInstance: Backup_Database.backup_task manual__2024-06-18T08:31:06.437365+00:00 [queued]>
[2024-06-18T14:17:10.822+0545] {taskinstance.py:2076} INFO - Dependencies all met for dep_context=requeueable deps ti=<TaskInstance: Backup_Database.backup_task manual__2024-06-18T08:31:06.437365+00:00 [queued]>
[2024-06-18T14:17:10.822+0545] {taskinstance.py:2306} INFO - Starting attempt 2 of 2
[2024-06-18T14:17:10.999+0545] {taskinstance.py:2330} INFO - Executing <Task(BashOperator): backup_task> on 2024-06-18 08:31:06.437365+00:00
[2024-06-18T14:17:11.006+0545] {standard_task_runner.py:63} INFO - Started process 17704 to run task
[2024-06-18T14:17:11.014+0545] {standard_task_runner.py:90} INFO - Running: ['airflow', 'tasks', 'run', 'Backup_Database', 'backup_task', 'manual__2024-06-18T08:31:06.437365+00:00', '--job-id', '46', '--raw', '--subdir', 'DAGS_FOLDER/basic_dag.py', '--cfg-path', '/tmp/tmpsjf83_4i']
[2024-06-18T14:17:11.019+0545] {standard_task_runner.py:91} INFO - Job 46: Subtask backup_task
[2024-06-18T14:17:11.264+0545] {task_command.py:426} INFO - Running <TaskInstance: Backup_Database.backup_task manual__2024-06-18T08:31:06.437365+00:00 [running]> on host manisha-Inspiron-3580
[2024-06-18T14:17:11.657+0545] {taskinstance.py:2648} INFO - Exporting env vars: AIRFLOW_CTX_DAG_OWNER='manisha' AIRFLOW_CTX_DAG_ID='Backup_Database' AIRFLOW_CTX_TASK_ID='backup_task' AIRFLOW_CTX_EXECUTION_DATE='2024-06-18T08:31:06.437365+00:00' AIRFLOW_CTX_TRY_NUMBER='2' AIRFLOW_CTX_DAG_RUN_ID='manual__2024-06-18T08:31:06.437365+00:00'
[2024-06-18T14:17:11.659+0545] {taskinstance.py:430} INFO - ::endgroup::
[2024-06-18T14:17:11.702+0545] {subprocess.py:63} INFO - Tmp dir root location: /tmp
[2024-06-18T14:17:11.703+0545] {subprocess.py:75} INFO - Running command: ['/usr/bin/bash', '-c', '/root/backup.sh ']
[2024-06-18T14:17:11.709+0545] {subprocess.py:86} INFO - Output:
[2024-06-18T14:17:11.710+0545] {subprocess.py:93} INFO - /usr/bin/bash: line 1: /root/backup.sh: Permission denied
[2024-06-18T14:17:11.710+0545] {subprocess.py:97} INFO - Command exited with return code 126
[2024-06-18T14:17:11.710+0545] {taskinstance.py:441} INFO - ::group::Post task execution logs
[2024-06-18T14:17:11.724+0545] {taskinstance.py:2905} ERROR - Task failed with exception
Traceback (most recent call last):
  File "/home/manisha/airflow_env/lib/python3.10/site-packages/airflow/models/taskinstance.py", line 465, in _execute_task
    result = _execute_callable(context=context, **execute_callable_kwargs)
  File "/home/manisha/airflow_env/lib/python3.10/site-packages/airflow/models/taskinstance.py", line 432, in _execute_callable
    return execute_callable(context=context, **execute_callable_kwargs)
  File "/home/manisha/airflow_env/lib/python3.10/site-packages/airflow/models/baseoperator.py", line 401, in wrapper
    return func(self, *args, **kwargs)
  File "/home/manisha/airflow_env/lib/python3.10/site-packages/airflow/operators/bash.py", line 243, in execute
    raise AirflowException(
airflow.exceptions.AirflowException: Bash command failed. The command returned a non-zero exit code 126.
[2024-06-18T14:17:11.728+0545] {taskinstance.py:1206} INFO - Marking task as FAILED. dag_id=Backup_Database, task_id=backup_task, run_id=manual__2024-06-18T08:31:06.437365+00:00, execution_date=20240618T083106, start_date=20240618T083210, end_date=20240618T083211
[2024-06-18T14:17:11.890+0545] {standard_task_runner.py:110} ERROR - Failed to execute job 46 for task backup_task (Bash command failed. The command returned a non-zero exit code 126.; 17704)
[2024-06-18T14:17:11.909+0545] {local_task_job_runner.py:240} INFO - Task exited with return code 1
[2024-06-18T14:17:11.946+0545] {taskinstance.py:3503} INFO - 0 downstream tasks scheduled from follow-on schedule check
[2024-06-18T14:17:12.066+0545] {local_task_job_runner.py:222} INFO - ::endgroup::
